[2022-05-31 16:06:27,067] {taskinstance.py:826} INFO - Dependencies all met for <TaskInstance: ClusterDAG_test.t1 2022-05-31T16:06:24.736708+00:00 [queued]>
[2022-05-31 16:06:27,152] {taskinstance.py:826} INFO - Dependencies all met for <TaskInstance: ClusterDAG_test.t1 2022-05-31T16:06:24.736708+00:00 [queued]>
[2022-05-31 16:06:27,152] {taskinstance.py:1017} INFO - 
--------------------------------------------------------------------------------
[2022-05-31 16:06:27,152] {taskinstance.py:1018} INFO - Starting attempt 1 of 1
[2022-05-31 16:06:27,152] {taskinstance.py:1019} INFO - 
--------------------------------------------------------------------------------
[2022-05-31 16:06:27,181] {taskinstance.py:1038} INFO - Executing <Task(BashOperator): t1> on 2022-05-31T16:06:24.736708+00:00
[2022-05-31 16:06:27,186] {standard_task_runner.py:51} INFO - Started process 9056 to run task
[2022-05-31 16:06:27,191] {standard_task_runner.py:75} INFO - Running: ['airflow', 'tasks', 'run', 'ClusterDAG_test', 't1', '2022-05-31T16:06:24.736708+00:00', '--job-id', '43', '--pool', 'default_pool', '--raw', '--subdir', 'DAGS_FOLDER/HelloDAG.py', '--cfg-path', '/tmp/tmpudaunqus']
[2022-05-31 16:06:27,191] {standard_task_runner.py:76} INFO - Job 43: Subtask t1
[2022-05-31 16:06:27,354] {logging_mixin.py:103} INFO - Running <TaskInstance: ClusterDAG_test.t1 2022-05-31T16:06:24.736708+00:00 [running]> on host slave01
[2022-05-31 16:06:27,527] {taskinstance.py:1232} INFO - Exporting the following env vars:
AIRFLOW_CTX_DAG_OWNER=airflow
AIRFLOW_CTX_DAG_ID=ClusterDAG_test
AIRFLOW_CTX_TASK_ID=t1
AIRFLOW_CTX_EXECUTION_DATE=2022-05-31T16:06:24.736708+00:00
AIRFLOW_CTX_DAG_RUN_ID=manual__2022-05-31T16:06:24.736708+00:00
[2022-05-31 16:06:27,528] {bash.py:135} INFO - Tmp dir root location: 
 /tmp
[2022-05-31 16:06:27,529] {bash.py:158} INFO - Running command: sleep 1
[2022-05-31 16:06:27,537] {bash.py:169} INFO - Output:
[2022-05-31 16:06:28,540] {bash.py:177} INFO - Command exited with return code 0
[2022-05-31 16:07:34,598] {taskinstance.py:1396} ERROR - (_mysql_exceptions.OperationalError) (2006, "Can't connect to MySQL server on '192.168.0.29' (113)")
(Background on this error at: http://sqlalche.me/e/13/e3q8)
Traceback (most recent call last):
  File "/usr/local/lib64/python3.6/site-packages/sqlalchemy/engine/base.py", line 2336, in _wrap_pool_connect
    return fn()
  File "/usr/local/lib64/python3.6/site-packages/sqlalchemy/pool/base.py", line 364, in connect
    return _ConnectionFairy._checkout(self)
  File "/usr/local/lib64/python3.6/site-packages/sqlalchemy/pool/base.py", line 778, in _checkout
    fairy = _ConnectionRecord.checkout(pool)
  File "/usr/local/lib64/python3.6/site-packages/sqlalchemy/pool/base.py", line 495, in checkout
    rec = pool._do_get()
  File "/usr/local/lib64/python3.6/site-packages/sqlalchemy/pool/impl.py", line 241, in _do_get
    return self._create_connection()
  File "/usr/local/lib64/python3.6/site-packages/sqlalchemy/pool/base.py", line 309, in _create_connection
    return _ConnectionRecord(self)
  File "/usr/local/lib64/python3.6/site-packages/sqlalchemy/pool/base.py", line 440, in __init__
    self.__connect(first_connect_check=True)
  File "/usr/local/lib64/python3.6/site-packages/sqlalchemy/pool/base.py", line 661, in __connect
    pool.logger.debug("Error on connect(): %s", e)
  File "/usr/local/lib64/python3.6/site-packages/sqlalchemy/util/langhelpers.py", line 70, in __exit__
    with_traceback=exc_tb,
  File "/usr/local/lib64/python3.6/site-packages/sqlalchemy/util/compat.py", line 182, in raise_
    raise exception
  File "/usr/local/lib64/python3.6/site-packages/sqlalchemy/pool/base.py", line 656, in __connect
    connection = pool._invoke_creator(self)
  File "/usr/local/lib64/python3.6/site-packages/sqlalchemy/engine/strategies.py", line 114, in connect
    return dialect.connect(*cargs, **cparams)
  File "/usr/local/lib64/python3.6/site-packages/sqlalchemy/engine/default.py", line 508, in connect
    return self.dbapi.connect(*cargs, **cparams)
  File "/usr/local/lib64/python3.6/site-packages/MySQLdb/__init__.py", line 85, in Connect
    return Connection(*args, **kwargs)
  File "/usr/local/lib64/python3.6/site-packages/MySQLdb/connections.py", line 208, in __init__
    super(Connection, self).__init__(*args, **kwargs2)
_mysql_exceptions.OperationalError: (2006, "Can't connect to MySQL server on '192.168.0.29' (113)")

The above exception was the direct cause of the following exception:

Traceback (most recent call last):
  File "/usr/local/lib/python3.6/site-packages/airflow/models/taskinstance.py", line 1086, in _run_raw_task
    self._prepare_and_execute_task_with_callbacks(context, task)
  File "/usr/local/lib/python3.6/site-packages/airflow/models/taskinstance.py", line 1260, in _prepare_and_execute_task_with_callbacks
    result = self._execute_task(context, task_copy)
  File "/usr/local/lib/python3.6/site-packages/airflow/models/taskinstance.py", line 1303, in _execute_task
    self.xcom_push(key=XCOM_RETURN_KEY, value=result)
  File "/usr/local/lib/python3.6/site-packages/airflow/utils/session.py", line 65, in wrapper
    return func(*args, session=session, **kwargs)
  File "/usr/local/lib/python3.6/site-packages/airflow/models/taskinstance.py", line 1833, in xcom_push
    session=session,
  File "/usr/local/lib/python3.6/site-packages/airflow/utils/session.py", line 62, in wrapper
    return func(*args, **kwargs)
  File "/usr/local/lib/python3.6/site-packages/airflow/models/xcom.py", line 92, in set
    cls.key == key, cls.execution_date == execution_date, cls.task_id == task_id, cls.dag_id == dag_id
  File "/usr/local/lib64/python3.6/site-packages/sqlalchemy/orm/query.py", line 3926, in delete
    delete_op.exec_()
  File "/usr/local/lib64/python3.6/site-packages/sqlalchemy/orm/persistence.py", line 1697, in exec_
    self._do_exec()
  File "/usr/local/lib64/python3.6/site-packages/sqlalchemy/orm/persistence.py", line 1930, in _do_exec
    self._execute_stmt(delete_stmt)
  File "/usr/local/lib64/python3.6/site-packages/sqlalchemy/orm/persistence.py", line 1702, in _execute_stmt
    self.result = self.query._execute_crud(stmt, self.mapper)
  File "/usr/local/lib64/python3.6/site-packages/sqlalchemy/orm/query.py", line 3565, in _execute_crud
    mapper=mapper, clause=stmt, close_with_result=True
  File "/usr/local/lib64/python3.6/site-packages/sqlalchemy/orm/query.py", line 3550, in _connection_from_session
    conn = self.session.connection(**kw)
  File "/usr/local/lib64/python3.6/site-packages/sqlalchemy/orm/session.py", line 1145, in connection
    execution_options=execution_options,
  File "/usr/local/lib64/python3.6/site-packages/sqlalchemy/orm/session.py", line 1151, in _connection_for_bind
    engine, execution_options
  File "/usr/local/lib64/python3.6/site-packages/sqlalchemy/orm/session.py", line 433, in _connection_for_bind
    conn = bind._contextual_connect()
  File "/usr/local/lib64/python3.6/site-packages/sqlalchemy/engine/base.py", line 2302, in _contextual_connect
    self._wrap_pool_connect(self.pool.connect, None),
  File "/usr/local/lib64/python3.6/site-packages/sqlalchemy/engine/base.py", line 2340, in _wrap_pool_connect
    e, dialect, self
  File "/usr/local/lib64/python3.6/site-packages/sqlalchemy/engine/base.py", line 1584, in _handle_dbapi_exception_noconnection
    sqlalchemy_exception, with_traceback=exc_info[2], from_=e
  File "/usr/local/lib64/python3.6/site-packages/sqlalchemy/util/compat.py", line 182, in raise_
    raise exception
  File "/usr/local/lib64/python3.6/site-packages/sqlalchemy/engine/base.py", line 2336, in _wrap_pool_connect
    return fn()
  File "/usr/local/lib64/python3.6/site-packages/sqlalchemy/pool/base.py", line 364, in connect
    return _ConnectionFairy._checkout(self)
  File "/usr/local/lib64/python3.6/site-packages/sqlalchemy/pool/base.py", line 778, in _checkout
    fairy = _ConnectionRecord.checkout(pool)
  File "/usr/local/lib64/python3.6/site-packages/sqlalchemy/pool/base.py", line 495, in checkout
    rec = pool._do_get()
  File "/usr/local/lib64/python3.6/site-packages/sqlalchemy/pool/impl.py", line 241, in _do_get
    return self._create_connection()
  File "/usr/local/lib64/python3.6/site-packages/sqlalchemy/pool/base.py", line 309, in _create_connection
    return _ConnectionRecord(self)
  File "/usr/local/lib64/python3.6/site-packages/sqlalchemy/pool/base.py", line 440, in __init__
    self.__connect(first_connect_check=True)
  File "/usr/local/lib64/python3.6/site-packages/sqlalchemy/pool/base.py", line 661, in __connect
    pool.logger.debug("Error on connect(): %s", e)
  File "/usr/local/lib64/python3.6/site-packages/sqlalchemy/util/langhelpers.py", line 70, in __exit__
    with_traceback=exc_tb,
  File "/usr/local/lib64/python3.6/site-packages/sqlalchemy/util/compat.py", line 182, in raise_
    raise exception
  File "/usr/local/lib64/python3.6/site-packages/sqlalchemy/pool/base.py", line 656, in __connect
    connection = pool._invoke_creator(self)
  File "/usr/local/lib64/python3.6/site-packages/sqlalchemy/engine/strategies.py", line 114, in connect
    return dialect.connect(*cargs, **cparams)
  File "/usr/local/lib64/python3.6/site-packages/sqlalchemy/engine/default.py", line 508, in connect
    return self.dbapi.connect(*cargs, **cparams)
  File "/usr/local/lib64/python3.6/site-packages/MySQLdb/__init__.py", line 85, in Connect
    return Connection(*args, **kwargs)
  File "/usr/local/lib64/python3.6/site-packages/MySQLdb/connections.py", line 208, in __init__
    super(Connection, self).__init__(*args, **kwargs2)
sqlalchemy.exc.OperationalError: (_mysql_exceptions.OperationalError) (2006, "Can't connect to MySQL server on '192.168.0.29' (113)")
(Background on this error at: http://sqlalche.me/e/13/e3q8)
[2022-05-31 16:07:34,616] {taskinstance.py:1440} INFO - Marking task as FAILED. dag_id=ClusterDAG_test, task_id=t1, execution_date=20220531T160624, start_date=20220531T160627, end_date=20220531T160734
[2022-05-31 16:07:37,627] {base_job.py:222} ERROR - LocalTaskJob heartbeat got an exception
Traceback (most recent call last):
  File "/usr/local/lib64/python3.6/site-packages/sqlalchemy/engine/base.py", line 2336, in _wrap_pool_connect
    return fn()
  File "/usr/local/lib64/python3.6/site-packages/sqlalchemy/pool/base.py", line 364, in connect
    return _ConnectionFairy._checkout(self)
  File "/usr/local/lib64/python3.6/site-packages/sqlalchemy/pool/base.py", line 778, in _checkout
    fairy = _ConnectionRecord.checkout(pool)
  File "/usr/local/lib64/python3.6/site-packages/sqlalchemy/pool/base.py", line 495, in checkout
    rec = pool._do_get()
  File "/usr/local/lib64/python3.6/site-packages/sqlalchemy/pool/impl.py", line 241, in _do_get
    return self._create_connection()
  File "/usr/local/lib64/python3.6/site-packages/sqlalchemy/pool/base.py", line 309, in _create_connection
    return _ConnectionRecord(self)
  File "/usr/local/lib64/python3.6/site-packages/sqlalchemy/pool/base.py", line 440, in __init__
    self.__connect(first_connect_check=True)
  File "/usr/local/lib64/python3.6/site-packages/sqlalchemy/pool/base.py", line 661, in __connect
    pool.logger.debug("Error on connect(): %s", e)
  File "/usr/local/lib64/python3.6/site-packages/sqlalchemy/util/langhelpers.py", line 70, in __exit__
    with_traceback=exc_tb,
  File "/usr/local/lib64/python3.6/site-packages/sqlalchemy/util/compat.py", line 182, in raise_
    raise exception
  File "/usr/local/lib64/python3.6/site-packages/sqlalchemy/pool/base.py", line 656, in __connect
    connection = pool._invoke_creator(self)
  File "/usr/local/lib64/python3.6/site-packages/sqlalchemy/engine/strategies.py", line 114, in connect
    return dialect.connect(*cargs, **cparams)
  File "/usr/local/lib64/python3.6/site-packages/sqlalchemy/engine/default.py", line 508, in connect
    return self.dbapi.connect(*cargs, **cparams)
  File "/usr/local/lib64/python3.6/site-packages/MySQLdb/__init__.py", line 85, in Connect
    return Connection(*args, **kwargs)
  File "/usr/local/lib64/python3.6/site-packages/MySQLdb/connections.py", line 208, in __init__
    super(Connection, self).__init__(*args, **kwargs2)
_mysql_exceptions.OperationalError: (2006, "Can't connect to MySQL server on '192.168.0.29' (113)")

The above exception was the direct cause of the following exception:

Traceback (most recent call last):
  File "/usr/local/lib/python3.6/site-packages/airflow/jobs/base_job.py", line 194, in heartbeat
    session.merge(self)
  File "/usr/local/lib64/python3.6/site-packages/sqlalchemy/orm/session.py", line 2171, in merge
    _resolve_conflict_map=_resolve_conflict_map,
  File "/usr/local/lib64/python3.6/site-packages/sqlalchemy/orm/session.py", line 2244, in _merge
    merged = self.query(mapper.class_).get(key[1])
  File "/usr/local/lib64/python3.6/site-packages/sqlalchemy/orm/query.py", line 1018, in get
    return self._get_impl(ident, loading.load_on_pk_identity)
  File "/usr/local/lib64/python3.6/site-packages/sqlalchemy/orm/query.py", line 1135, in _get_impl
    return db_load_fn(self, primary_key_identity)
  File "/usr/local/lib64/python3.6/site-packages/sqlalchemy/orm/loading.py", line 286, in load_on_pk_identity
    return q.one()
  File "/usr/local/lib64/python3.6/site-packages/sqlalchemy/orm/query.py", line 3490, in one
    ret = self.one_or_none()
  File "/usr/local/lib64/python3.6/site-packages/sqlalchemy/orm/query.py", line 3459, in one_or_none
    ret = list(self)
  File "/usr/local/lib64/python3.6/site-packages/sqlalchemy/orm/query.py", line 3535, in __iter__
    return self._execute_and_instances(context)
  File "/usr/local/lib64/python3.6/site-packages/sqlalchemy/orm/query.py", line 3557, in _execute_and_instances
    querycontext, self._connection_from_session, close_with_result=True
  File "/usr/local/lib64/python3.6/site-packages/sqlalchemy/orm/query.py", line 3572, in _get_bind_args
    mapper=self._bind_mapper(), clause=querycontext.statement, **kw
  File "/usr/local/lib64/python3.6/site-packages/sqlalchemy/orm/query.py", line 3550, in _connection_from_session
    conn = self.session.connection(**kw)
  File "/usr/local/lib64/python3.6/site-packages/sqlalchemy/orm/session.py", line 1145, in connection
    execution_options=execution_options,
  File "/usr/local/lib64/python3.6/site-packages/sqlalchemy/orm/session.py", line 1151, in _connection_for_bind
    engine, execution_options
  File "/usr/local/lib64/python3.6/site-packages/sqlalchemy/orm/session.py", line 433, in _connection_for_bind
    conn = bind._contextual_connect()
  File "/usr/local/lib64/python3.6/site-packages/sqlalchemy/engine/base.py", line 2302, in _contextual_connect
    self._wrap_pool_connect(self.pool.connect, None),
  File "/usr/local/lib64/python3.6/site-packages/sqlalchemy/engine/base.py", line 2340, in _wrap_pool_connect
    e, dialect, self
  File "/usr/local/lib64/python3.6/site-packages/sqlalchemy/engine/base.py", line 1584, in _handle_dbapi_exception_noconnection
    sqlalchemy_exception, with_traceback=exc_info[2], from_=e
  File "/usr/local/lib64/python3.6/site-packages/sqlalchemy/util/compat.py", line 182, in raise_
    raise exception
  File "/usr/local/lib64/python3.6/site-packages/sqlalchemy/engine/base.py", line 2336, in _wrap_pool_connect
    return fn()
  File "/usr/local/lib64/python3.6/site-packages/sqlalchemy/pool/base.py", line 364, in connect
    return _ConnectionFairy._checkout(self)
  File "/usr/local/lib64/python3.6/site-packages/sqlalchemy/pool/base.py", line 778, in _checkout
    fairy = _ConnectionRecord.checkout(pool)
  File "/usr/local/lib64/python3.6/site-packages/sqlalchemy/pool/base.py", line 495, in checkout
    rec = pool._do_get()
  File "/usr/local/lib64/python3.6/site-packages/sqlalchemy/pool/impl.py", line 241, in _do_get
    return self._create_connection()
  File "/usr/local/lib64/python3.6/site-packages/sqlalchemy/pool/base.py", line 309, in _create_connection
    return _ConnectionRecord(self)
  File "/usr/local/lib64/python3.6/site-packages/sqlalchemy/pool/base.py", line 440, in __init__
    self.__connect(first_connect_check=True)
  File "/usr/local/lib64/python3.6/site-packages/sqlalchemy/pool/base.py", line 661, in __connect
    pool.logger.debug("Error on connect(): %s", e)
  File "/usr/local/lib64/python3.6/site-packages/sqlalchemy/util/langhelpers.py", line 70, in __exit__
    with_traceback=exc_tb,
  File "/usr/local/lib64/python3.6/site-packages/sqlalchemy/util/compat.py", line 182, in raise_
    raise exception
  File "/usr/local/lib64/python3.6/site-packages/sqlalchemy/pool/base.py", line 656, in __connect
    connection = pool._invoke_creator(self)
  File "/usr/local/lib64/python3.6/site-packages/sqlalchemy/engine/strategies.py", line 114, in connect
    return dialect.connect(*cargs, **cparams)
  File "/usr/local/lib64/python3.6/site-packages/sqlalchemy/engine/default.py", line 508, in connect
    return self.dbapi.connect(*cargs, **cparams)
  File "/usr/local/lib64/python3.6/site-packages/MySQLdb/__init__.py", line 85, in Connect
    return Connection(*args, **kwargs)
  File "/usr/local/lib64/python3.6/site-packages/MySQLdb/connections.py", line 208, in __init__
    super(Connection, self).__init__(*args, **kwargs2)
sqlalchemy.exc.OperationalError: (_mysql_exceptions.OperationalError) (2006, "Can't connect to MySQL server on '192.168.0.29' (113)")
(Background on this error at: http://sqlalche.me/e/13/e3q8)
[2022-05-31 16:07:37,640] {local_task_job.py:118} INFO - Task exited with return code 1
